Workbook

Sheet Pre-processing
A2: Script Table | B2: Script.txt
A3: // Modifies the X position of line end B
A4: //
A5: //
C7: Select "Pipe"
A8: // Case | B8: LoadData | C8: EndBX = | D8: SaveData
A9: 01 | B9: "basecase.dat" | C9: -363 | D9: ="Case0"&A9&".dat" -> Case001.dat
A10: 02 | C10: -364 | D10: ="Case0"&A10&".dat" -> Case002.dat
A11: 03 | C11: -365 | D11: ="Case0"&A11&".dat" -> Case003.dat
A12: 04 | C12: -366 | D12: ="Case0"&A12&".dat" -> Case004.dat
A13: 05 | C13: -367 | D13: ="Case0"&A13&".dat" -> Case005.dat
A14: 06 | C14: -368 | D14: ="Case0"&A14&".dat" -> Case006.dat
A15: 07 | C15: -369 | D15: ="Case0"&A15&".dat" -> Case007.dat
A16: 08 | C16: -370 | D16: ="Case0"&A16&".dat" -> Case008.dat
A17: 09 | C17: -371 | D17: ="Case0"&A17&".dat" -> Case009.dat
A18: 10 | C18: -372 | D18: ="Case0"&A18&".dat" -> Case010.dat
A19: 11 | C19: -373 | D19: ="Case0"&A19&".dat" -> Case011.dat
A20: 12 | C20: -374 | D20: ="Case0"&A20&".dat" -> Case012.dat
A21: 13 | C21: -375 | D21: ="Case0"&A21&".dat" -> Case013.dat
... A26: 18 | C26: -380 | D26: ="Case0"&A26&".dat" -> Case018.dat

Sheet General Post-processing
A3: Sheet | B3: Label | D3: Output | F3: Object | G3: Additional | H3: Simulation
A4: Name | B4: Cell | C4: Label | D4: Cell | E4: Command | F4: Name | G4: Data | H4: Period | I4: Variable
A5: General Results | E5: Clear
E6: Load Case001.sim
A7: General Results | B7: B1 | C7: =RIGHT(E6,LEN(E6)-5) -> Case001.sim
A8: General Results | B8: A2 | C8: Pipe Bottom End Position | D8: B2 | E8: Static Result | F8: Pipe | G8: End B | I8: X
A9: General Results | B9: A3 | C9: Support 1 Reaction Force | D9: B3 | E9: Static Result | F9: Vessel1 | G9: SupportIndex=1 | I9: Support Reaction Force
A10: General Results | B10: A4 | C10: Support 2 Reaction Force | D10: B4 | E10: Static Result | F10: Vessel1 | G10: SupportIndex=2 | I10: Support Reaction Force
A11: General Results | B11: A5 | C11: Support 3 Reaction Force | D11: B5 | E11: Static Result | F11: Vessel1 | G11: SupportIndex=3 | I11: Support Reaction Force
A12: General Results | B12: A6 | C12: Support 4 Reaction Force | D12: B6 | E12: Static Result | F12: Vessel1 | G12: SupportIndex=4 | I12: Support Reaction Force
A13: General Results | B13: A7 | C13: Support 5 Reaction Force | D13: B7 | E13: Static Result | F13: Vessel1 | G13: SupportIndex=5 | I13: Support Reaction Force
A14: General Results | B14: A8 | C14: Max Support Lift Out | D14: B8 | E14: Static Result | F14: Vessel1 | G14: SupportedLineName=Pipe | I14: Max Support Lift Out
A15: General Results | B15: A9 | C15: Top Tension | D15: B9 | E15: Static Result | F15: Pipe | G15: End A | I15: Effective Tension
A16: General Results | B16: A10 | C16: Pipe Effective Tension (Touchdown) | D16: B10 | E16: Static Result | F16: Pipe | G16: Touchdown | I16: Effective Tension
A17: General Results | B17: A11 | C17: Top Bend Moment | D17: B11 | E17: Static Result | F17: Pipe | G17: End A | I17: Bend Moment
A18: General Results | B18: A12 | C18: Suspended Length | D18: B12 | E18: Static Result | F18: Pipe | G18: Touchdown | I18: Arc Length
A19: General Results | B19: A13 | C19: Touchdown Position | D19: B13 | E19: Static Result | F19: Pipe | G19: Touchdown | I19: X
... A23: General Results | B23: A17 | C23: Pipe End Lx-Force (End A) | D23: B17 | E23: Static Result | F23: Pipe | G23: End A | I23: End Lx-Force
A24: General Results | B24: A18 | C24: Vessel1 Name | D24: B18 | E24: Get Data | F24: Vessel1 | I24: Name
A25: General Results | B25: A19 | C25: 8" x 14mm Type Name | D25: B19 | E25: Get Data | F25: 8" x 14mm Type | I25: Name
A26: General Results | B26: A20 | C26: Top End Declination | D26: B20 | E26: Static Result | F26: Pipe | G26: End A | I26: Declination
A27: General Results | B27: A21 | C27: Environment WaterDepth | D27: B21 | E27: Get Data | F27: Environment | I27: WaterDepth
A28: General Results | B28: A22 | C28: Environment SeabedSlope | D28: B22 | E28: Get Data | F28: Environment | I28: SeabedSlope
A29: General Results | B29: A23 | C29: Environment RefCurrentSpeed | D29: B23 | E29: Get Data | F29: Environment | I29: RefCurrentSpeed
A30: General Results | B30: A24 | C30: Environment CurrentFactor[1] | D30: B24 | E30: Get Data | F30: Environment | I30: CurrentFactor[1]
A31: General Results | B31: A25 | C31: Environment CurrentFactor[2] | D31: B25 | E31: Get Data | F31: Environment | I31: CurrentFactor[2]
A32: General Results | B32: A26 | C32: Environment RefCurrentDirection | D32: B26 | E32: Get Data | F32: Environment | I32: RefCurrentDirection
A33: General Results | B33: A27 | C33: API CODE CHECK SMYS | D33: B27 | E33: Get Data | F33: 8" x 14mm Type | I33: APIRP1111S
A34: General Results | B34: A28 | C34: Pipe API RP 1111 Max Combined | D34: B28 | E34: Range Graph Max | F34: Pipe | I34: API RP 1111 Max Combined
A35: General Results | B35: A29 | C35: Pipe Minimum Tension | D35: B29 | E35: Range Graph Min | F35: Pipe | I35: Effective Tension
E36: Load Case002.sim
A37: General Results | B37: D1 | C37: =RIGHT(E36,LEN(E36)-5) -> Case002.sim
A38: General Results | B38: C2 | C38: Pipe Bottom End Position | D38: D2 | E38: Static Result | F38: Pipe | G38: End B | I38: X
A39: General Results | B39: C3 | C39: Support 1 Reaction Force | D39: D3 | E39: Static Result | F39: Vessel1 | G39: SupportIndex=1 | I39: Support Reaction Force
A40: General Results | B40: C4 | C40: Support 2 Reaction Force | D40: D4 | E40: Static Result | F40: Vessel1 | G40: SupportIndex=2 | I40: Support Reaction Force
A41: General Results | B41: C5 | C41: Support 3 Reaction Force | D41: D5 | E41: Static Result | F41: Vessel1 | G41: SupportIndex=3 | I41: Support Reaction Force
A42: General Results | B42: C6 | C42: Support 4 Reaction Force | D42: D6 | E42: Static Result | F42: Vessel1 | G42: SupportIndex=4 | I42: Support Reaction Force
A43: General Results | B43: C7 | C43: Support 5 Reaction Force | D43: D7 | E43: Static Result | F43: Vessel1 | G43: SupportIndex=5 | I43: Support Reaction Force
A44: General Results | B44: C8 | C44: Max Support Lift Out | D44: D8 | E44: Static Result | F44: Vessel1 | G44: SupportedLineName=Pipe | I44: Max Support Lift Out
A45: General Results | B45: C9 | C45: Top Tension | D45: D9 | E45: Static Result | F45: Pipe | G45: End A | I45: Effective Tension
...

Sheet __$Orcina_Hidden_Sheet$__
A1: Duplicate - Script file name | B1: Script.txt | C1: ArcLength | D1: 0 | E1: Version | F1: 9.9a5
A2: Duplicate - Sheet base name | B2: Results | C2: BatchName | D2: APIRP1111S | E2: Requires | F2: 9.3c1 | H2: IgnoreErrors | I2: FALSE
A3: Duplicate - Xoffset | B3: 6 | C3: OverwriteLabels | D3: TRUE | H3: ContainsDependencies | I3: FALSE
A4: Duplicate - Yoffset | B4: 0 | C4: ClearanceLineindex | D4: 65500 | H4: InstructionsSheetIndex | I4: 4
A5: Duplicate - Different sheets | B5: 1 | C5: Command | D5: 26
A6: Duplicate - Specified Files | B6: 0 | C6: Position.X | D6: 0
A7: Duplicate - Number of Files | B7: 18 | C7: Position.Y | D7: 0
A8: Duplicate - Duplicate Labels | B8: TRUE | C8: Position.Z (Global) | D8: 0
A9: Duplicate - Sheet name method | B9: 0 | C9: FileName | D9: Case020.sim
C10: FromArcLength | D10: 0
C11: GetDataIndex | D11: 2
C12: InsertMethod | D12: 0
C13: Label | D13: Pipe Minimum Tension
C14: LabelCell | D14: B29
C15: LinePosition | D15: 0
C16: NodeNumber | D16: 5
C17: ObjectIndex | D17: 7
C18: OutputCell | D18: C29
C19: Position.Z (Local) | D19: 0
C20: Period | D20: 2
C21: Radius | D21: 0
C22: ArcLengthRange | D22: 0
C23: SubObject | D23: 0
C24: ResultsSheetName | D24: General Results
C25: SpecifiedPeriodFrom | D25: -8
C26: SpecifiedPeriodTo | D26: 16
C27: Theta | D27: 0
C28: ToArcLength | D28: 0
C29: UseDefaultLabel | D29: FALSE
C30: SelectedVarIDs | D30: nnnnnnnnnnynnnnnnnnnnnnnnnnnnnnnnnnnnnnnnnnnnnnnnnnnnnnnnnnnnnnnnnnnnnnnnnnnnnnnnnnnnnnnnnnnnnnnnnnnnnnnnnnnnnnnnnnnnnnnnnnnnnnnnnnnnnnnnnnnnnnnnnnnnnnnnnnnnnnnnnnnnnnnnnnnnnnnnnnnnnnnnnnnnnnnnnnnnnnnnnnnnnnnnnnnnnnnnnnnnnnnnnnnnnnnnnnnnnnnnnnnnnnnnnnnnnnn
C31: WinchConnectionPoint | D31: 1
C32: WingIndex | D32: 0
C33: Section | D33: 1
C34: ClearSheetName | D34: Results
C35: SourceSheetName | D35: RG Template Sheet
C36: DestinationSheetName | D36: Range Graph Results NEW
C37: RangeMin | D37: FALSE
C38: RangeMax | D38: TRUE
C39: RangeMean | D39: FALSE
C40: RangeStdDev | D40: FALSE
...

Sheet Range Graphs Post-processing
A3: Sheet | B3: Label | D3: Output | F3: Object | G3: Additional | H3: Simulation
A4: Name | B4: Cell | C4: Label | D4: Cell | E4: Command | F4: Name | G4: Data | H4: Period | I4: Variable
E5: Load Case001.sim
A6: Range Graph Results | B6: A1 | C6: =E5 -> Load Case001.sim
A7: Range Graph Results | B7: A2 | C7: Pipe Declination | D7: A3 | E7: Range Graph | F7: Pipe | I7: Declination
A8: Range Graph Results | B8: D2 | C8: Max Von Mises Stress | D8: D3 | E8: Range Graph | F8: Pipe | I8: Max von Mises Stress
E9: Load Case002.sim
A10: Range Graph Results | B10: G1 | C10: =E9 -> Load Case002.sim
A11: Range Graph Results | B11: G2 | C11: Pipe Declination | D11: G3 | E11: Range Graph | F11: Pipe | I11: Declination
A12: Range Graph Results | B12: J2 | C12: Max Von Mises Stress | D12: J3 | E12: Range Graph | F12: Pipe | I12: Max von Mises Stress
E13: Load Case003.sim
A14: Range Graph Results | B14: M1 | C14: =E13 -> Load Case003.sim
A15: Range Graph Results | B15: M2 | C15: Pipe Declination | D15: M3 | E15: Range Graph | F15: Pipe | I15: Declination
A16: Range Graph Results | B16: P2 | C16: Max Von Mises Stress | D16: P3 | E16: Range Graph | F16: Pipe | I16: Max von Mises Stress
E17: Load Case004.sim
A18: Range Graph Results | B18: S1 | C18: =E17 -> Load Case004.sim
A19: Range Graph Results | B19: S2 | C19: Pipe Declination | D19: S3 | E19: Range Graph | F19: Pipe | I19: Declination
A20: Range Graph Results | B20: V2 | C20: Max Von Mises Stress | D20: V3 | E20: Range Graph | F20: Pipe | I20: Max von Mises Stress
E21: Load Case005.sim
A22: Range Graph Results | B22: Y1 | C22: =E21 -> Load Case005.sim
A23: Range Graph Results | B23: Y2 | C23: Pipe Declination | D23: Y3 | E23: Range Graph | F23: Pipe | I23: Declination
A24: Range Graph Results | B24: AB2 | C24: Max Von Mises Stress | D24: AB3 | E24: Range Graph | F24: Pipe | I24: Max von Mises Stress
E25: Load Case006.sim
A26: Range Graph Results | B26: AE1 | C26: =E25 -> Load Case006.sim
A27: Range Graph Results | B27: AE2 | C27: Pipe Declination | D27: AE3 | E27: Range Graph | F27: Pipe | I27: Declination
A28: Range Graph Results | B28: AH2 | C28: Max Von Mises Stress | D28: AH3 | E28: Range Graph | F28: Pipe | I28: Max von Mises Stress
E29: Load Case007.sim
A30: Range Graph Results | B30: AK1 | C30: =E29 -> Load Case007.sim
A31: Range Graph Results | B31: AK2 | C31: Pipe Declination | D31: AK3 | E31: Range Graph | F31: Pipe | I31: Declination
A32: Range Graph Results | B32: AN2 | C32: Max Von Mises Stress | D32: AN3 | E32: Range Graph | F32: Pipe | I32: Max von Mises Stress
E33: Load Case008.sim
A34: Range Graph Results | B34: AQ1 | C34: =E33 -> Load Case008.sim
A35: Range Graph Results | B35: AQ2 | C35: Pipe Declination | D35: AQ3 | E35: Range Graph | F35: Pipe | I35: Declination
A36: Range Graph Results | B36: AT2 | C36: Max Von Mises Stress | D36: AT3 | E36: Range Graph | F36: Pipe | I36: Max von Mises Stress
E37: Load Case009.sim
A38: Range Graph Results | B38: AW1 | C38: =E37 -> Load Case009.sim
A39: Range Graph Results | B39: AW2 | C39: Pipe Declination | D39: AW3 | E39: Range Graph | F39: Pipe | I39: Declination
A40: Range Graph Results | B40: AZ2 | C40: Max Von Mises Stress | D40: AZ3 | E40: Range Graph | F40: Pipe | I40: Max von Mises Stress
E41: Load Case010.sim
A42: Range Graph Results | B42: BC1 | C42: =E41 -> Load Case010.sim
...

Sheet Final Results
B2: OrcaFlex Pipelay Table (OrcaFlex Spreadsheet)
B4: Basecase Data | E4: Comments: This results sheet is intended to replicate a typical OrcaLay results sheet as a way of demonstrating that OrcaFlex can be used as a viable alternative. It is an example of the type of data that can be automatically presented through the OrcaFlex spreadsheet. Basecase data is retrieved automatically from the OrcaFlex results, with only minimal input required on this sheet (user input required in the yellow cells only). Cells and rows are highlighted automatically to identify pass/fail. Cells highlighted in red are those that do not meet the necessary acceptance criteria. Rows highlighted in green represent the 'acceptable' cases that remain within all acceptance criteria. If the reaction force for all supports in a load case is zero, this infers that the line is completely in sagbend, and this will consequently place "N/A" in the corresponding overbend cell. User needs will of course vary, and this sheet is only intended as an example.
B5: Vessel: | C5: ='General Results'!B18 -> Vessel1
B6: Pipe: | C6: ='General Results'!B19 -> 8" x 14mm Type
B7: Ramp Angle (deg): | C7: ='General Results'!B20-90 -> 50
B8: Water Depth (m): | C8: ='General Results'!B21 -> 120
B9: Seabed Slope: | C9: ='General Results'!B22 -> 0
B10: Current Speed (surface): | C10: ='General Results'!B23*'General Results'!B24 -> 0
B11: Current Speed (seabed): | C11: ='General Results'!B23*'General Results'!B25 -> 0
B12: Current Direction (deg): | C12: ='General Results'!B26 -> 180
B13: Code Check: | C13: API RP 1111
B15: Acceptance Criteria
B16: Max Tension (kN): | C16: 250
B17: Min Tension (kN): | C17: 0
B18: Max Bollard Pull (kN): | C18: 500
B19: Uncontrolled Stress Limit (kPa, 72% of yield) | C19: ='General Results'!B27*0.72/1000 -> 257.76
B20: Controlled Stress Limit (kPa, 96% of yield) | C20: ='General Results'!B27*0.96/1000 -> 343.68
B23: Load Case | C23: Anchor X Position | D23: Support Reaction Force | I23: Max Support Lift Out | J23: Tension | L23: Minimum Tension | M23: Top Bend Moment | N23: Suspended Length | O23: Horizontal Projection | P23: Projection Growth | Q23: Maximum Stress | S23: Departure Angle | T23: Constraint Clearance | U23: Code Check | V23: Bollard Pull
D24: 1 | E24: 2 | F24: 3 | G24: 4 | H24: 5 | J24: Top | K24: Bottom | Q24: Overbend | R24: Sagbend
C25: m | D25: kN | E25: kN | F25: kN | G25: kN | H25: kN | I25: m | J25: kN | K25: kN | L25: kN | M25: kN.m | N25: m | O25: m | P25: m | Q25: kPa | R25: kPa | S25: deg | T25: m | V25: kN
A26: 1 | B26: =OFFSET('General Results'!$A$1,0,1+($A26-1)*2) -> Case001.sim | C26: =OFFSET('General Results'!$A$1,1,1+($A26-1)*2) -> -363 | D26: =OFFSET('General Results'!$A$1,2,1+($A26-1)*2) -> 0 | E26: =OFFSET('General Results'!$A$1,3,1+($A26-1)*2) -> 0 | F26: =OFFSET('General Results'!$A$1,4,1+($A26-1)*2) -> 0 | G26: =OFFSET('General Results'!$A$1,5,1+($A26-1)*2) -> 0 | H26: =OFFSET('General Results'!$A$1,6,1+($A26-1)*2) -> 41.556872 | I26: =OFFSET('General Results'!$A$1,7,1+($A26-1)*2) -> 0.51063645 | J26: =OFFSET('General Results'!$A$1,8,1+($A26-1)*2) -> 154.03787 | K26: =OFFSET('General Results'!$A$1,9,1+($A26-1)*2) -> 62.742976 | L26: =OFFSET('General Results'!B$29,,(A26-1)*2) -> 54.346949 | M26: =OFFSET('General Results'!$A$1,10,1+($A26-1)*2) -> 0.6588452 | N26: =OFFSET('General Results'!$A$1,11,1+($A26-1)*2) -> 234 | O26: =ABS(OFFSET('General Results'!$A$1,12,1+($A26-1)*2))-ABS(OFFSET('General Results'!$A$1,13,1+($A26-1)*2)) -> 173.47738 | P26: =N26-O26 -> 60.522623 | Q26: {=IF(SUM($D26:$H26)>0,(MAX(IF((OFFSET('Range Graph Results'!C$4:C$385,,($A26-1)*6)>=0),OFFSET('Range Graph Results'!E$4:E$385,,($A26-1)*6))))/1000,"N/A")} -> 360.66199 | R26: {=(MAX(IF((OFFSET('Range Graph Results'!C$4:C$385,,($A26-1)*6)<0),OFFSET('Range Graph Results'!E$4:E$385,,($A26-1)*6))))/1000} -> 182.90159 | S26: =(OFFSET('General Results'!$A$1,14,1+($A26-1)*2))-90 -> 55.22937 | T26: =OFFSET('General Results'!$A$1,15,1+($A26-1)*2) -> 1.6506071 | U26: =IF(OFFSET('General Results'!B$28,,($A26-1)*2)<1,"PASS","FAIL") -> PASS | V26: =ABS(OFFSET('General Results'!$A$1,16,1+($A26-1)*2)) -> 96.203827
A27: 2 | B27: =OFFSET('General Results'!$A$1,0,1+($A27-1)*2) -> Case002.sim | C27: =OFFSET('General Results'!$A$1,1,1+($A27-1)*2) -> -364 | D27: =OFFSET('General Results'!$A$1,2,1+($A27-1)*2) -> 0 | E27: =OFFSET('General Results'!$A$1,3,1+($A27-1)*2) -> 0 | F27: =OFFSET('General Results'!$A$1,4,1+($A27-1)*2) -> 0 | G27: =OFFSET('General Results'!$A$1,5,1+($A27-1)*2) -> 0 | H27: =OFFSET('General Results'!$A$1,6,1+($A27-1)*2) -> 39.702376 | I27: =OFFSET('General Results'!$A$1,7,1+($A27-1)*2) -> 0.49523783 | J27: =OFFSET('General Results'!$A$1,8,1+($A27-1)*2) -> 157.56666 | K27: =OFFSET('General Results'!$A$1,9,1+($A27-1)*2) -> 66.280059 | L27: =OFFSET('General Results'!B$29,,(A27-1)*2) -> 57.735303 | M27: =OFFSET('General Results'!$A$1,10,1+($A27-1)*2) -> 3.5263795 | N27: =OFFSET('General Results'!$A$1,11,1+($A27-1)*2) -> 238 | O27: =ABS(OFFSET('General Results'!$A$1,12,1+($A27-1)*2))-ABS(OFFSET('General Results'!$A$1,13,1+($A27-1)*2)) -> 178.47713 | P27: =N27-O27 -> 59.522866 | Q27: {=IF(SUM($D27:$H27)>0,(MAX(IF((OFFSET('Range Graph Results'!C$4:C$385,,($A27-1)*6)>=0),OFFSET('Range Graph Results'!E$4:E$385,,($A27-1)*6))))/1000,"N/A")} -> 338.22433 | R27: {=(MAX(IF((OFFSET('Range Graph Results'!C$4:C$385,,($A27-1)*6)<0),OFFSET('Range Graph Results'!E$4:E$385,,($A27-1)*6))))/1000} -> 175.5993 | S27: =(OFFSET('General Results'!$A$1,14,1+($A27-1)*2))-90 -> 54.804227 | T27: =OFFSET('General Results'!$A$1,15,1+($A27-1)*2) -> 1.6668381 | U27: =IF(OFFSET('General Results'!B$28,,($A27-1)*2)<1,"PASS","FAIL") -> PASS | V27: =ABS(OFFSET('General Results'!$A$1,16,1+($A27-1)*2)) -> 98.115447
A28: 3 | B28: =OFFSET('General Results'!$A$1,0,1+($A28-1)*2) -> Case003.sim | C28: =OFFSET('General Results'!$A$1,1,1+($A28-1)*2) -> -365 | D28: =OFFSET('General Results'!$A$1,2,1+($A28-1)*2) -> 0 | E28: =OFFSET('General Results'!$A$1,3,1+($A28-1)*2) -> 0 | F28: =OFFSET('General Results'!$A$1,4,1+($A28-1)*2) -> 0 | G28: =OFFSET('General Results'!$A$1,5,1+($A28-1)*2) -> 0 | H28: =OFFSET('General Results'!$A$1,6,1+($A28-1)*2) -> 37.725758 | I28: =OFFSET('General Results'!$A$1,7,1+($A28-1)*2) -> 0.47954527 | J28: =OFFSET('General Results'!$A$1,8,1+($A28-1)*2) -> 161.31206 | K28: =OFFSET('General Results'!$A$1,9,1+($A28-1)*2) -> 70.028859 | L28: =OFFSET('General Results'!B$29,,(A28-1)*2) -> 61.400542 | M28: =OFFSET('General Results'!$A$1,10,1+($A28-1)*2) -> 6.4455689 | N28: =OFFSET('General Results'!$A$1,11,1+($A28-1)*2) -> 241 | O28: =ABS(OFFSET('General Results'!$A$1,12,1+($A28-1)*2))-ABS(OFFSET('General Results'!$A$1,13,1+($A28-1)*2)) -> 182.47694 | P28: =N28-O28 -> 58.523057 | Q28: {=IF(SUM($D28:$H28)>0,(MAX(IF((OFFSET('Range Graph Results'!C$4:C$385,,($A28-1)*6)>=0),OFFSET('Range Graph Results'!E$4:E$385,,($A28-1)*6))))/1000,"N/A")} -> 315.03319 | R28: {=(MAX(IF((OFFSET('Range Graph Results'!C$4:C$385,,($A28-1)*6)<0),OFFSET('Range Graph Results'!E$4:E$385,,($A28-1)*6))))/1000} -> 168.51094 | S28: =(OFFSET('General Results'!$A$1,14,1+($A28-1)*2))-90 -> 54.367758 | T28: =OFFSET('General Results'!$A$1,15,1+($A28-1)*2) -> 1.6833345 | U28: =IF(OFFSET('General Results'!B$28,,($A28-1)*2)<1,"PASS","FAIL") -> PASS | V28: =ABS(OFFSET('General Results'!$A$1,16,1+($A28-1)*2)) -> 100.15533
A29: 4 | B29: =OFFSET('General Results'!$A$1,0,1+($A29-1)*2) -> Case004.sim | C29: =OFFSET('General Results'!$A$1,1,1+($A29-1)*2) -> -366 | D29: =OFFSET('General Results'!$A$1,2,1+($A29-1)*2) -> 1.1306148 | E29: =OFFSET('General Results'!$A$1,3,1+($A29-1)*2) -> 0 | F29: =OFFSET('General Results'!$A$1,4,1+($A29-1)*2) -> 0 | G29: =OFFSET('General Results'!$A$1,5,1+($A29-1)*2) -> 0 | H29: =OFFSET('General Results'!$A$1,6,1+($A29-1)*2) -> 35.511886 | I29: =OFFSET('General Results'!$A$1,7,1+($A29-1)*2) -> 0.46515911 | J29: =OFFSET('General Results'!$A$1,8,1+($A29-1)*2) -> 165.29867 | K29: =OFFSET('General Results'!$A$1,9,1+($A29-1)*2) -> 74.020096 | L29: =OFFSET('General Results'!B$29,,(A29-1)*2) -> 65.313411 | M29: =OFFSET('General Results'!$A$1,10,1+($A29-1)*2) -> 6.0817249 | N29: =OFFSET('General Results'!$A$1,11,1+($A29-1)*2) -> 245 | O29: =ABS(OFFSET('General Results'!$A$1,12,1+($A29-1)*2))-ABS(OFFSET('General Results'!$A$1,13,1+($A29-1)*2)) -> 187.47672 | P29: =N29-O29 -> 57.523279 | Q29: {=IF(SUM($D29:$H29)>0,(MAX(IF((OFFSET('Range Graph Results'!C$4:C$385,,($A29-1)*6)>=0),OFFSET('Range Graph Results'!E$4:E$385,,($A29-1)*6))))/1000,"N/A")} -> 290.31171 | R29: {=(MAX(IF((OFFSET('Range Graph Results'!C$4:C$385,,($A29-1)*6)<0),OFFSET('Range Graph Results'!E$4:E$385,,($A29-1)*6))))/1000} -> 161.64613 | S29: =(OFFSET('General Results'!$A$1,14,1+($A29-1)*2))-90 -> 53.930386 | T29: =OFFSET('General Results'!$A$1,15,1+($A29-1)*2) -> 1.6968605 | U29: =IF(OFFSET('General Results'!B$28,,($A29-1)*2)<1,"PASS","FAIL") -> PASS | V29: =ABS(OFFSET('General Results'!$A$1,16,1+($A29-1)*2)) -> 103.12643
A30: 5 | B30: =OFFSET('General Results'!$A$1,0,1+($A30-1)*2) -> Case005.sim | C30: =OFFSET('General Results'!$A$1,1,1+($A30-1)*2) -> -367 | D30: =OFFSET('General Results'!$A$1,2,1+($A30-1)*2) -> 2.5834275 | E30: =OFFSET('General Results'!$A$1,3,1+($A30-1)*2) -> 0 | F30: =OFFSET('General Results'!$A$1,4,1+($A30-1)*2) -> 0 | G30: =OFFSET('General Results'!$A$1,5,1+($A30-1)*2) -> 0 | H30: =OFFSET('General Results'!$A$1,6,1+($A30-1)*2) -> 33.122942 | I30: =OFFSET('General Results'!$A$1,7,1+($A30-1)*2) -> 0.45089761 | J30: =OFFSET('General Results'!$A$1,8,1+($A30-1)*2) -> 169.54466 | K30: =OFFSET('General Results'!$A$1,9,1+($A30-1)*2) -> 78.267307 | L30: =OFFSET('General Results'!B$29,,(A30-1)*2) -> 69.521471 | M30: =OFFSET('General Results'!$A$1,10,1+($A30-1)*2) -> 4.8443952 | N30: =OFFSET('General Results'!$A$1,11,1+($A30-1)*2) -> 249 | O30: =ABS(OFFSET('General Results'!$A$1,12,1+($A30-1)*2))-ABS(OFFSET('General Results'!$A$1,13,1+($A30-1)*2)) -> 192.47651 | P30: =N30-O30 -> 56.52349 | Q30: {=IF(SUM($D30:$H30)>0,(MAX(IF((OFFSET('Range Graph Results'!C$4:C$385,,($A30-1)*6)>=0),OFFSET('Range Graph Results'!E$4:E$385,,($A30-1)*6))))/1000,"N/A")} -> 264.62195 | R30: {=(MAX(IF((OFFSET('Range Graph Results'!C$4:C$385,,($A30-1)*6)<0),OFFSET('Range Graph Results'!E$4:E$385,,($A30-1)*6))))/1000} -> 154.99957 | S30: =(OFFSET('General Results'!$A$1,14,1+($A30-1)*2))-90 -> 53.483572 | T30: =OFFSET('General Results'!$A$1,15,1+($A30-1)*2) -> 1.7097838 | U30: =IF(OFFSET('General Results'!B$28,,($A30-1)*2)<1,"PASS","FAIL") -> PASS | V30: =ABS(OFFSET('General Results'!$A$1,16,1+($A30-1)*2)) -> 106.47579
A31: 6 | B31: =OFFSET('General Results'!$A$1,0,1+($A31-1)*2) -> Case006.sim | C31: =OFFSET('General Results'!$A$1,1,1+($A31-1)*2) -> -368 | D31: =OFFSET('General Results'!$A$1,2,1+($A31-1)*2) -> 4.0710016 | E31: =OFFSET('General Results'!$A$1,3,1+($A31-1)*2) -> 0 | F31: =OFFSET('General Results'!$A$1,4,1+($A31-1)*2) -> 0 | G31: =OFFSET('General Results'!$A$1,5,1+($A31-1)*2) -> 0 | H31: =OFFSET('General Results'!$A$1,6,1+($A31-1)*2) -> 30.571048 | I31: =OFFSET('General Results'!$A$1,7,1+($A31-1)*2) -> 0.43634559 | J31: =OFFSET('General Results'!$A$1,8,1+($A31-1)*2) -> 174.0665 | K31: =OFFSET('General Results'!$A$1,9,1+($A31-1)*2) -> 82.789787 | L31: =OFFSET('General Results'!B$29,,(A31-1)*2) -> 74.044459 | M31: =OFFSET('General Results'!$A$1,10,1+($A31-1)*2) -> 3.5872446 | N31: =OFFSET('General Results'!$A$1,11,1+($A31-1)*2) -> 253 | O31: =ABS(OFFSET('General Results'!$A$1,12,1+($A31-1)*2))-ABS(OFFSET('General Results'!$A$1,13,1+($A31-1)*2)) -> 197.47631 | P31: =N31-O31 -> 55.523693 | Q31: {=IF(SUM($D31:$H31)>0,(MAX(IF((OFFSET('Range Graph Results'!C$4:C$385,,($A31-1)*6)>=0),OFFSET('Range Graph Results'!E$4:E$385,,($A31-1)*6))))/1000,"N/A")} -> 238.01146 | R31: {=(MAX(IF((OFFSET('Range Graph Results'!C$4:C$385,,($A31-1)*6)<0),OFFSET('Range Graph Results'!E$4:E$385,,($A31-1)*6))))/1000} -> 148.59054 | S31: =(OFFSET('General Results'!$A$1,14,1+($A31-1)*2))-90 -> 53.02412 | T31: =OFFSET('General Results'!$A$1,15,1+($A31-1)*2) -> 1.722937 | U31: =IF(OFFSET('General Results'!B$28,,($A31-1)*2)<1,"PASS","FAIL") -> PASS | V31: =ABS(OFFSET('General Results'!$A$1,16,1+($A31-1)*2)) -> 110.01312
A32: 7 | B32: =OFFSET('General Results'!$A$1,0,1+($A32-1)*2) -> Case007.sim | C32: =OFFSET('General Results'!$A$1,1,1+($A32-1)*2) -> -369 | D32: =OFFSET('General Results'!$A$1,2,1+($A32-1)*2) -> 5.5939007 | E32: =OFFSET('General Results'!$A$1,3,1+($A32-1)*2) -> 0 | F32: =OFFSET('General Results'!$A$1,4,1+($A32-1)*2) -> 0 | G32: =OFFSET('General Results'!$A$1,5,1+($A32-1)*2) -> 0 | H32: =OFFSET('General Results'!$A$1,6,1+($A32-1)*2) -> 27.84076 | I32: =OFFSET('General Results'!$A$1,7,1+($A32-1)*2) -> 0.42150259 | J32: =OFFSET('General Results'!$A$1,8,1+($A32-1)*2) -> 178.88846 | K32: =OFFSET('General Results'!$A$1,9,1+($A32-1)*2) -> 87.61225 | L32: =OFFSET('General Results'!B$29,,(A32-1)*2) -> 78.907428 | M32: =OFFSET('General Results'!$A$1,10,1+($A32-1)*2) -> 2.3112733 | N32: =OFFSET('General Results'!$A$1,11,1+($A32-1)*2) -> 257 | O32: =ABS(OFFSET('General Results'!$A$1,12,1+($A32-1)*2))-ABS(OFFSET('General Results'!$A$1,13,1+($A32-1)*2)) -> 202.47611 | P32: =N32-O32 -> 54.523889 | Q32: {=IF(SUM($D32:$H32)>0,(MAX(IF((OFFSET('Range Graph Results'!C$4:C$385,,($A32-1)*6)>=0),OFFSET('Range Graph Results'!E$4:E$385,,($A32-1)*6))))/1000,"N/A")} -> 210.42666 | R32: {=(MAX(IF((OFFSET('Range Graph Results'!C$4:C$385,,($A32-1)*6)<0),OFFSET('Range Graph Results'!E$4:E$385,,($A32-1)*6))))/1000} -> 142.41438 | S32: =(OFFSET('General Results'!$A$1,14,1+($A32-1)*2))-90 -> 52.551558 | T32: =OFFSET('General Results'!$A$1,15,1+($A32-1)*2) -> 1.7363157 | U32: =IF(OFFSET('General Results'!B$28,,($A32-1)*2)<1,"PASS","FAIL") -> PASS | V32: =ABS(OFFSET('General Results'!$A$1,16,1+($A32-1)*2)) -> 113.75362
A33: 8 | B33: =OFFSET('General Results'!$A$1,0,1+($A33-1)*2) -> Case008.sim | C33: =OFFSET('General Results'!$A$1,1,1+($A33-1)*2) -> -370 | D33: =OFFSET('General Results'!$A$1,2,1+($A33-1)*2) -> 5.0513306 | E33: =OFFSET('General Results'!$A$1,3,1+($A33-1)*2) -> 1.5017647 | F33: =OFFSET('General Results'!$A$1,4,1+($A33-1)*2) -> 0 | G33: =OFFSET('General Results'!$A$1,5,1+($A33-1)*2) -> 0 | H33: =OFFSET('General Results'!$A$1,6,1+($A33-1)*2) -> 24.656666 | I33: =OFFSET('General Results'!$A$1,7,1+($A33-1)*2) -> 0.4094251 | J33: =OFFSET('General Results'!$A$1,8,1+($A33-1)*2) -> 184.04902 | K33: =OFFSET('General Results'!$A$1,9,1+($A33-1)*2) -> 92.773627 | L33: =OFFSET('General Results'!B$29,,(A33-1)*2) -> 84.149352 | M33: =OFFSET('General Results'!$A$1,10,1+($A33-1)*2) -> 2.2815441 | N33: =OFFSET('General Results'!$A$1,11,1+($A33-1)*2) -> 261 | O33: =ABS(OFFSET('General Results'!$A$1,12,1+($A33-1)*2))-ABS(OFFSET('General Results'!$A$1,13,1+($A33-1)*2)) -> 207.47593 | P33: =N33-O33 -> 53.524075 | Q33: {=IF(SUM($D33:$H33)>0,(MAX(IF((OFFSET('Range Graph Results'!C$4:C$385,,($A33-1)*6)>=0),OFFSET('Range Graph Results'!E$4:E$385,,($A33-1)*6))))/1000,"N/A")} -> 180.22194 | R33: {=(MAX(IF((OFFSET('Range Graph Results'!C$4:C$385,,($A33-1)*6)<0),OFFSET('Range Graph Results'!E$4:E$385,,($A33-1)*6))))/1000} -> 136.47422 | S33: =(OFFSET('General Results'!$A$1,14,1+($A33-1)*2))-90 -> 52.085838 | T33: =OFFSET('General Results'!$A$1,15,1+($A33-1)*2) -> 1.7443389 | U33: =IF(OFFSET('General Results'!B$28,,($A33-1)*2)<1,"PASS","FAIL") -> PASS | V33: =ABS(OFFSET('General Results'!$A$1,16,1+($A33-1)*2)) -> 117.06863
A34: 9 | B34: =OFFSET('General Results'!$A$1,0,1+($A34-1)*2) -> Case009.sim | C34: =OFFSET('General Results'!$A$1,1,1+($A34-1)*2) -> -371 | D34: =OFFSET('General Results'!$A$1,2,1+($A34-1)*2) -> 4.0372578 | E34: =OFFSET('General Results'!$A$1,3,1+($A34-1)*2) -> 3.3775933 | F34: =OFFSET('General Results'!$A$1,4,1+($A34-1)*2) -> 0 | G34: =OFFSET('General Results'!$A$1,5,1+($A34-1)*2) -> 0 | H34: =OFFSET('General Results'!$A$1,6,1+($A34-1)*2) -> 21.190796 | I34: =OFFSET('General Results'!$A$1,7,1+($A34-1)*2) -> 0.39773813 | J34: =OFFSET('General Results'!$A$1,8,1+($A34-1)*2) -> 189.57029 | K34: =OFFSET('General Results'!$A$1,9,1+($A34-1)*2) -> 98.296838 | L34: =OFFSET('General Results'!B$29,,(A34-1)*2) -> 89.813236 | M34: =OFFSET('General Results'!$A$1,10,1+($A34-1)*2) -> 2.5282145 | N34: =OFFSET('General Results'!$A$1,11,1+($A34-1)*2) -> 266 | O34: =ABS(OFFSET('General Results'!$A$1,12,1+($A34-1)*2))-ABS(OFFSET('General Results'!$A$1,13,1+($A34-1)*2)) -> 213.47574 | P34: =N34-O34 -> 52.52426 | Q34: {=IF(SUM($D34:$H34)>0,(MAX(IF((OFFSET('Range Graph Results'!C$4:C$385,,($A34-1)*6)>=0),OFFSET('Range Graph Results'!E$4:E$385,,($A34-1)*6))))/1000,"N/A")} -> 148.52579 | R34: {=(MAX(IF((OFFSET('Range Graph Results'!C$4:C$385,,($A34-1)*6)<0),OFFSET('Range Graph Results'!E$4:E$385,,($A34-1)*6))))/1000} -> 130.77106 | S34: =(OFFSET('General Results'!$A$1,14,1+($A34-1)*2))-90 -> 51.610152 | T34: =OFFSET('General Results'!$A$1,15,1+($A34-1)*2) -> 1.7513043 | U34: =IF(OFFSET('General Results'!B$28,,($A34-1)*2)<1,"PASS","FAIL") -> PASS | V34: =ABS(OFFSET('General Results'!$A$1,16,1+($A34-1)*2)) -> 120.47229
A35: 10 | B35: =OFFSET('General Results'!$A$1,0,1+($A35-1)*2) -> Case010.sim | C35: =OFFSET('General Results'!$A$1,1,1+($A35-1)*2) -> -372 | D35: =OFFSET('General Results'!$A$1,2,1+($A35-1)*2) -> 3.0677935 | E35: =OFFSET('General Results'!$A$1,3,1+($A35-1)*2) -> 5.1487184 | F35: =OFFSET('General Results'!$A$1,4,1+($A35-1)*2) -> 0.14303781 | G35: =OFFSET('General Results'!$A$1,5,1+($A35-1)*2) -> 0 | H35: =OFFSET('General Results'!$A$1,6,1+($A35-1)*2) -> 17.437887 | I35: =OFFSET('General Results'!$A$1,7,1+($A35-1)*2) -> 0.38606893 | J35: =OFFSET('General Results'!$A$1,8,1+($A35-1)*2) -> 195.48686 | K35: =OFFSET('General Results'!$A$1,9,1+($A35-1)*2) -> 104.21496 | L35: =OFFSET('General Results'!B$29,,(A35-1)*2) -> 95.927502 | M35: =OFFSET('General Results'!$A$1,10,1+($A35-1)*2) -> 2.7635686 | N35: =OFFSET('General Results'!$A$1,11,1+($A35-1)*2) -> 271 | O35: =ABS(OFFSET('General Results'!$A$1,12,1+($A35-1)*2))-ABS(OFFSET('General Results'!$A$1,13,1+($A35-1)*2)) -> 219.47557 | P35: =N35-O35 -> 51.524426 | Q35: {=IF(SUM($D35:$H35)>0,(MAX(IF((OFFSET('Range Graph Results'!C$4:C$385,,($A35-1)*6)>=0),OFFSET('Range Graph Results'!E$4:E$385,,($A35-1)*6))))/1000,"N/A")} -> 115.4366 | R35: {=(MAX(IF((OFFSET('Range Graph Results'!C$4:C$385,,($A35-1)*6)<0),OFFSET('Range Graph Results'!E$4:E$385,,($A35-1)*6))))/1000} -> 125.31972 | S35: =(OFFSET('General Results'!$A$1,14,1+($A35-1)*2))-90 -> 51.121441 | T35: =OFFSET('General Results'!$A$1,15,1+($A35-1)*2) -> 1.7580566 | U35: =IF(OFFSET('General Results'!B$28,,($A35-1)*2)<1,"PASS","FAIL") -> PASS | V35: =ABS(OFFSET('General Results'!$A$1,16,1+($A35-1)*2)) -> 124.13647
A36: 11 | B36: =OFFSET('General Results'!$A$1,0,1+($A36-1)*2) -> Case011.sim | C36: =OFFSET('General Results'!$A$1,1,1+($A36-1)*2) -> -373 | D36: =OFFSET('General Results'!$A$1,2,1+($A36-1)*2) -> 3.2688897 | E36: =OFFSET('General Results'!$A$1,3,1+($A36-1)*2) -> 4.0381661 | F36: =OFFSET('General Results'!$A$1,4,1+($A36-1)*2) -> 2.929021 | G36: =OFFSET('General Results'!$A$1,5,1+($A36-1)*2) -> 0 | H36: =OFFSET('General Results'!$A$1,6,1+($A36-1)*2) -> 12.715838 | I36: =OFFSET('General Results'!$A$1,7,1+($A36-1)*2) -> 0.37950917 | J36: =OFFSET('General Results'!$A$1,8,1+($A36-1)*2) -> 201.85277 | K36: =OFFSET('General Results'!$A$1,9,1+($A36-1)*2) -> 110.5832 | L36: =OFFSET('General Results'!B$29,,(A36-1)*2) -> 102.54748 | M36: =OFFSET('General Results'!$A$1,10,1+($A36-1)*2) -> 2.7281805 | N36: =OFFSET('General Results'!$A$1,11,1+($A36-1)*2) -> 276 | O36: =ABS(OFFSET('General Results'!$A$1,12,1+($A36-1)*2))-ABS(OFFSET('General Results'!$A$1,13,1+($A36-1)*2)) -> 225.47543 | P36: =N36-O36 -> 50.524574 | Q36: {=IF(SUM($D36:$H36)>0,(MAX(IF((OFFSET('Range Graph Results'!C$4:C$385,,($A36-1)*6)>=0),OFFSET('Range Graph Results'!E$4:E$385,,($A36-1)*6))))/1000,"N/A")} -> 77.95335 | R36: {=(MAX(IF((OFFSET('Range Graph Results'!C$4:C$385,,($A36-1)*6)<0),OFFSET('Range Graph Results'!E$4:E$385,,($A36-1)*6))))/1000} -> 120.10401 | S36: =(OFFSET('General Results'!$A$1,14,1+($A36-1)*2))-90 -> 50.655149 | T36: =OFFSET('General Results'!$A$1,15,1+($A36-1)*2) -> 1.7583389 | U36: =IF(OFFSET('General Results'!B$28,,($A36-1)*2)<1,"PASS","FAIL") -> PASS | V36: =ABS(OFFSET('General Results'!$A$1,16,1+($A36-1)*2)) -> 128.24962
A37: 12 | B37: =OFFSET('General Results'!$A$1,0,1+($A37-1)*2) -> Case012.sim | C37: =OFFSET('General Results'!$A$1,1,1+($A37-1)*2) -> -374 | D37: =OFFSET('General Results'!$A$1,2,1+($A37-1)*2) -> 3.3493424 | E37: =OFFSET('General Results'!$A$1,3,1+($A37-1)*2) -> 3.6199766 | F37: =OFFSET('General Results'!$A$1,4,1+($A37-1)*2) -> 3.6786701 | G37: =OFFSET('General Results'!$A$1,5,1+($A37-1)*2) -> 2.733623 | H37: =OFFSET('General Results'!$A$1,6,1+($A37-1)*2) -> 6.4328379 | I37: =OFFSET('General Results'!$A$1,7,1+($A37-1)*2) -> 0.37632597 | J37: =OFFSET('General Results'!$A$1,8,1+($A37-1)*2) -> 208.71427 | K37: =OFFSET('General Results'!$A$1,9,1+($A37-1)*2) -> 117.44787 | L37: =OFFSET('General Results'!B$29,,(A37-1)*2) -> 109.74542 | M37: =OFFSET('General Results'!$A$1,10,1+($A37-1)*2) -> 2.7151919 | N37: =OFFSET('General Results'!$A$1,11,1+($A37-1)*2) -> 281 | O37: =ABS(OFFSET('General Results'!$A$1,12,1+($A37-1)*2))-ABS(OFFSET('General Results'!$A$1,13,1+($A37-1)*2)) -> 231.4753 | P37: =N37-O37 -> 49.524705 | Q37: {=IF(SUM($D37:$H37)>0,(MAX(IF((OFFSET('Range Graph Results'!C$4:C$385,,($A37-1)*6)>=0),OFFSET('Range Graph Results'!E$4:E$385,,($A37-1)*6))))/1000,"N/A")} -> 36.160856 | R37: {=(MAX(IF((OFFSET('Range Graph Results'!C$4:C$385,,($A37-1)*6)<0),OFFSET('Range Graph Results'!E$4:E$385,,($A37-1)*6))))/1000} -> 115.13584 | S37: =(OFFSET('General Results'!$A$1,14,1+($A37-1)*2))-90 -> 50.20752 | T37: =OFFSET('General Results'!$A$1,15,1+($A37-1)*2) -> 1.7584148 | U37: =IF(OFFSET('General Results'!B$28,,($A37-1)*2)<1,"PASS","FAIL") -> PASS | V37: =ABS(OFFSET('General Results'!$A$1,16,1+($A37-1)*2)) -> 132.66733
... A43: 18 | B43: =OFFSET('General Results'!$A$1,0,1+($A43-1)*2) -> Case018.sim | C43: =OFFSET('General Results'!$A$1,1,1+($A43-1)*2) -> -380 | D43: =OFFSET('General Results'!$A$1,2,1+($A43-1)*2) -> 0 | E43: =OFFSET('General Results'!$A$1,3,1+($A43-1)*2) -> 0 | F43: =OFFSET('General Results'!$A$1,4,1+($A43-1)*2) -> 0 | G43: =OFFSET('General Results'!$A$1,5,1+($A43-1)*2) -> 0 | H43: =OFFSET('General Results'!$A$1,6,1+($A43-1)*2) -> 0 | I43: =OFFSET('General Results'!$A$1,7,1+($A43-1)*2) -> 1.3336976 | J43: =OFFSET('General Results'!$A$1,8,1+($A43-1)*2) -> 256.49743 | K43: =OFFSET('General Results'!$A$1,9,1+($A43-1)*2) -> 165.28192 | L43: =OFFSET('General Results'!B$29,,(A43-1)*2) -> 160.84384 | M43: =OFFSET('General Results'!$A$1,10,1+($A43-1)*2) -> 25.047463 | N43: =OFFSET('General Results'!$A$1,11,1+($A43-1)*2) -> 318 | O43: =ABS(OFFSET('General Results'!$A$1,12,1+($A43-1)*2))-ABS(OFFSET('General Results'!$A$1,13,1+($A43-1)*2)) -> 274.47553 | P43: =N43-O43 -> 43.52447 | Q43: {=IF(SUM($D43:$H43)>0,(MAX(IF((OFFSET('Range Graph Results'!C$4:C$385,,($A43-1)*6)>=0),OFFSET('Range Graph Results'!E$4:E$385,,($A43-1)*6))))/1000,"N/A")} -> N/A | R43: {=(MAX(IF((OFFSET('Range Graph Results'!C$4:C$385,,($A43-1)*6)<0),OFFSET('Range Graph Results'!E$4:E$385,,($A43-1)*6))))/1000} -> 98.604388 | S43: =(OFFSET('General Results'!$A$1,14,1+($A43-1)*2))-90 -> 45.453564 | T43: =OFFSET('General Results'!$A$1,15,1+($A43-1)*2) -> 1.4053527 | U43: =IF(OFFSET('General Results'!B$28,,($A43-1)*2)<1,"PASS","FAIL") -> PASS | V43: =ABS(OFFSET('General Results'!$A$1,16,1+($A43-1)*2)) -> 165.29074

Sheet General Results
B1: Case001.sim | D1: Case002.sim | F1: Case003.sim | H1: Case004.sim | J1: Case005.sim | L1: Case006.sim | N1: Case007.sim | P1: Case008.sim | R1: Case009.sim | T1: Case010.sim | V1: Case011.sim | X1: Case012.sim | Z1: Case013.sim | AB1: Case014.sim | AD1: Case015.sim | AF1: Case016.sim | AH1: Case017.sim | AJ1: Case018.sim
A2: Pipe Bottom End Position | B2: -363 | C2: Pipe Bottom End Position | D2: -364 | E2: Pipe Bottom End Position | F2: -365 | G2: Pipe Bottom End Position | H2: -366 | I2: Pipe Bottom End Position | J2: -367 | K2: Pipe Bottom End Position | L2: -368 | M2: Pipe Bottom End Position | N2: -369 | O2: Pipe Bottom End Position | P2: -370 | Q2: Pipe Bottom End Position | R2: -371 | S2: Pipe Bottom End Position | T2: -372 | U2: Pipe Bottom End Position | V2: -373 | W2: Pipe Bottom End Position | X2: -374 | Y2: Pipe Bottom End Position | Z2: -375 | AA2: Pipe Bottom End Position | AB2: -376 | AC2: Pipe Bottom End Position | AD2: -377 | AE2: Pipe Bottom End Position | AF2: -378 | AG2: Pipe Bottom End Position | AH2: -379 | AI2: Pipe Bottom End Position | AJ2: -380
A3: Support 1 Reaction Force | B3: 0 | C3: Support 1 Reaction Force | D3: 0 | E3: Support 1 Reaction Force | F3: 0 | G3: Support 1 Reaction Force | H3: 1.1306148 | I3: Support 1 Reaction Force | J3: 2.5834275 | K3: Support 1 Reaction Force | L3: 4.0710016 | M3: Support 1 Reaction Force | N3: 5.5939007 | O3: Support 1 Reaction Force | P3: 5.0513306 | Q3: Support 1 Reaction Force | R3: 4.0372578 | S3: Support 1 Reaction Force | T3: 3.0677935 | U3: Support 1 Reaction Force | V3: 3.2688897 | W3: Support 1 Reaction Force | X3: 3.3493424 | Y3: Support 1 Reaction Force | Z3: 3.3577157 | AA3: Support 1 Reaction Force | AB3: 3.2330708 | AC3: Support 1 Reaction Force | AD3: 4.0968014 | AE3: Support 1 Reaction Force | AF3: 4.6228401 | AG3: Support 1 Reaction Force | AH3: 0 | AI3: Support 1 Reaction Force | AJ3: 0
A4: Support 2 Reaction Force | B4: 0 | C4: Support 2 Reaction Force | D4: 0 | E4: Support 2 Reaction Force | F4: 0 | G4: Support 2 Reaction Force | H4: 0 | I4: Support 2 Reaction Force | J4: 0 | K4: Support 2 Reaction Force | L4: 0 | M4: Support 2 Reaction Force | N4: 0 | O4: Support 2 Reaction Force | P4: 1.5017647 | Q4: Support 2 Reaction Force | R4: 3.3775933 | S4: Support 2 Reaction Force | T4: 5.1487184 | U4: Support 2 Reaction Force | V4: 4.0381661 | W4: Support 2 Reaction Force | X4: 3.6199766 | Y4: Support 2 Reaction Force | Z4: 3.5957954 | AA4: Support 2 Reaction Force | AB4: 4.161221 | AC4: Support 2 Reaction Force | AD4: 5.2993336 | AE4: Support 2 Reaction Force | AF4: 0 | AG4: Support 2 Reaction Force | AH4: 0 | AI4: Support 2 Reaction Force | AJ4: 0
A5: Support 3 Reaction Force | B5: 0 | C5: Support 3 Reaction Force | D5: 0 | E5: Support 3 Reaction Force | F5: 0 | G5: Support 3 Reaction Force | H5: 0 | I5: Support 3 Reaction Force | J5: 0 | K5: Support 3 Reaction Force | L5: 0 | M5: Support 3 Reaction Force | N5: 0 | O5: Support 3 Reaction Force | P5: 0 | Q5: Support 3 Reaction Force | R5: 0 | S5: Support 3 Reaction Force | T5: 0.14303781 | U5: Support 3 Reaction Force | V5: 2.929021 | W5: Support 3 Reaction Force | X5: 3.6786701 | Y5: Support 3 Reaction Force | Z5: 3.6916618 | AA5: Support 3 Reaction Force | AB5: 5.4563515 | AC5: Support 3 Reaction Force | AD5: 0 | AE5: Support 3 Reaction Force | AF5: 0 | AG5: Support 3 Reaction Force | AH5: 0 | AI5: Support 3 Reaction Force | AJ5: 0
A6: Support 4 Reaction Force | B6: 0 | C6: Support 4 Reaction Force | D6: 0 | E6: Support 4 Reaction Force | F6: 0 | G6: Support 4 Reaction Force | H6: 0 | I6: Support 4 Reaction Force | J6: 0 | K6: Support 4 Reaction Force | L6: 0 | M6: Support 4 Reaction Force | N6: 0 | O6: Support 4 Reaction Force | P6: 0 | Q6: Support 4 Reaction Force | R6: 0 | S6: Support 4 Reaction Force | T6: 0 | U6: Support 4 Reaction Force | V6: 0 | W6: Support 4 Reaction Force | X6: 2.733623 | Y6: Support 4 Reaction Force | Z6: 5.7484474 | AA6: Support 4 Reaction Force | AB6: 0 | AC6: Support 4 Reaction Force | AD6: 0 | AE6: Support 4 Reaction Force | AF6: 0 | AG6: Support 4 Reaction Force | AH6: 0 | AI6: Support 4 Reaction Force | AJ6: 0
A7: Support 5 Reaction Force | B7: 41.556872 | C7: Support 5 Reaction Force | D7: 39.702376 | E7: Support 5 Reaction Force | F7: 37.725758 | G7: Support 5 Reaction Force | H7: 35.511886 | I7: Support 5 Reaction Force | J7: 33.122942 | K7: Support 5 Reaction Force | L7: 30.571048 | M7: Support 5 Reaction Force | N7: 27.84076 | O7: Support 5 Reaction Force | P7: 24.656666 | Q7: Support 5 Reaction Force | R7: 21.190796 | S7: Support 5 Reaction Force | T7: 17.437887 | U7: Support 5 Reaction Force | V7: 12.715838 | W7: Support 5 Reaction Force | X7: 6.4328379 | Y7: Support 5 Reaction Force | Z7: 0 | AA7: Support 5 Reaction Force | AB7: 0 | AC7: Support 5 Reaction Force | AD7: 0 | AE7: Support 5 Reaction Force | AF7: 0 | AG7: Support 5 Reaction Force | AH7: 0 | AI7: Support 5 Reaction Force | AJ7: 0
A8: Max Support Lift Out | B8: 0.51063645 | C8: Max Support Lift Out | D8: 0.49523783 | E8: Max Support Lift Out | F8: 0.47954527 | G8: Max Support Lift Out | H8: 0.46515911 | I8: Max Support Lift Out | J8: 0.45089761 | K8: Max Support Lift Out | L8: 0.43634559 | M8: Max Support Lift Out | N8: 0.42150259 | O8: Max Support Lift Out | P8: 0.4094251 | Q8: Max Support Lift Out | R8: 0.39773813 | S8: Max Support Lift Out | T8: 0.38606893 | U8: Max Support Lift Out | V8: 0.37950917 | W8: Max Support Lift Out | X8: 0.37632597 | Y8: Max Support Lift Out | Z8: 0.38274183 | AA8: Max Support Lift Out | AB8: 0.43827443 | AC8: Max Support Lift Out | AD8: 0.56259813 | AE8: Max Support Lift Out | AF8: 0.7604668 | AG8: Max Support Lift Out | AH8: 1.0316352 | AI8: Max Support Lift Out | AJ8: 1.3336976
A9: Top Tension | B9: 154.03787 | C9: Top Tension | D9: 157.56666 | E9: Top Tension | F9: 161.31206 | G9: Top Tension | H9: 165.29867 | I9: Top Tension | J9: 169.54466 | K9: Top Tension | L9: 174.0665 | M9: Top Tension | N9: 178.88846 | O9: Top Tension | P9: 184.04902 | Q9: Top Tension | R9: 189.57029 | S9: Top Tension | T9: 195.48686 | U9: Top Tension | V9: 201.85277 | W9: Top Tension | X9: 208.71427 | Y9: Top Tension | Z9: 216.06518 | AA9: Top Tension | AB9: 223.63533 | AC9: Top Tension | AD9: 231.43759 | AE9: Top Tension | AF9: 239.48389 | AG9: Top Tension | AH9: 247.78343 | AI9: Top Tension | AJ9: 256.49743
A10: Pipe Effective Tension (Touchdown) | B10: 62.742976 | C10: Pipe Effective Tension (Touchdown) | D10: 66.280059 | E10: Pipe Effective Tension (Touchdown) | F10: 70.028859 | G10: Pipe Effective Tension (Touchdown) | H10: 74.020096 | I10: Pipe Effective Tension (Touchdown) | J10: 78.267307 | K10: Pipe Effective Tension (Touchdown) | L10: 82.789787 | M10: Pipe Effective Tension (Touchdown) | N10: 87.61225 | O10: Pipe Effective Tension (Touchdown) | P10: 92.773627 | Q10: Pipe Effective Tension (Touchdown) | R10: 98.296838 | S10: Pipe Effective Tension (Touchdown) | T10: 104.21496 | U10: Pipe Effective Tension (Touchdown) | V10: 110.5832 | W10: Pipe Effective Tension (Touchdown) | X10: 117.44787 | Y10: Pipe Effective Tension (Touchdown) | Z10: 124.80267 | AA10: Pipe Effective Tension (Touchdown) | AB10: 132.37274 | AC10: Pipe Effective Tension (Touchdown) | AD10: 140.17671 | AE10: Pipe Effective Tension (Touchdown) | AF10: 148.22663 | AG10: Pipe Effective Tension (Touchdown) | AH10: 156.52734 | AI10: Pipe Effective Tension (Touchdown) | AJ10: 165.28192
A11: Top Bend Moment | B11: 0.6588452 | C11: Top Bend Moment | D11: 3.5263795 | E11: Top Bend Moment | F11: 6.4455689 | G11: Top Bend Moment | H11: 6.0817249 | I11: Top Bend Moment | J11: 4.8443952 | K11: Top Bend Moment | L11: 3.5872446 | M11: Top Bend Moment | N11: 2.3112733 | O11: Top Bend Moment | P11: 2.2815441 | Q11: Top Bend Moment | R11: 2.5282145 | S11: Top Bend Moment | T11: 2.7635686 | U11: Top Bend Moment | V11: 2.7281805 | W11: Top Bend Moment | X11: 2.7151919 | Y11: Top Bend Moment | Z11: 2.715862 | AA11: Top Bend Moment | AB11: 2.7432435 | AC11: Top Bend Moment | AD11: 2.5027104 | AE11: Top Bend Moment | AF11: 4.1895261 | AG11: Top Bend Moment | AH11: 2.3938445 | AI11: Top Bend Moment | AJ11: 25.047463
A12: Suspended Length | B12: 234 | C12: Suspended Length | D12: 238 | E12: Suspended Length | F12: 241 | G12: Suspended Length | H12: 245 | I12: Suspended Length | J12: 249 | K12: Suspended Length | L12: 253 | M12: Suspended Length | N12: 257 | O12: Suspended Length | P12: 261 | Q12: Suspended Length | R12: 266 | S12: Suspended Length | T12: 271 | U12: Suspended Length | V12: 276 | W12: Suspended Length | X12: 281 | Y12: Suspended Length | Z12: 287 | AA12: Suspended Length | AB12: 293 | AC12: Suspended Length | AD12: 299 | AE12: Suspended Length | AF12: 305 | AG12: Suspended Length | AH12: 311 | AI12: Suspended Length | AJ12: 318
A13: Touchdown Position | B13: -216.99672 | C13: Touchdown Position | D13: -221.99648 | E13: Touchdown Position | F13: -225.99629 | G13: Touchdown Position | H13: -230.99607 | I13: Touchdown Position | J13: -235.99585 | K13: Touchdown Position | L13: -240.99565 | M13: Touchdown Position | N13: -245.99546 | O13: Touchdown Position | P13: -250.99527 | Q13: Touchdown Position | R13: -256.99508 | S13: Touchdown Position | T13: -262.99492 | U13: Touchdown Position | V13: -268.99477 | W13: Touchdown Position | X13: -274.99464 | Y13: Touchdown Position | Z13: -281.99455 | AA13: Touchdown Position | AB13: -288.99451 | AC13: Touchdown Position | AD13: -295.99451 | AE13: Touchdown Position | AF13: -302.99456 | AG13: Touchdown Position | AH13: -309.99467 | AI13: Touchdown Position | AJ13: -317.99487
... A17: Pipe End Lx-Force (End A) | B17: -96.203827 | C17: Pipe End Lx-Force (End A) | D17: -98.115447 | E17: Pipe End Lx-Force (End A) | F17: -100.15533 | G17: Pipe End Lx-Force (End A) | H17: -103.12643 | I17: Pipe End Lx-Force (End A) | J17: -106.47579 | K17: Pipe End Lx-Force (End A) | L17: -110.01312 | M17: Pipe End Lx-Force (End A) | N17: -113.75362 | O17: Pipe End Lx-Force (End A) | P17: -117.06863 | Q17: Pipe End Lx-Force (End A) | R17: -120.47229 | S17: Pipe End Lx-Force (End A) | T17: -124.13647 | U17: Pipe End Lx-Force (End A) | V17: -128.24962 | W17: Pipe End Lx-Force (End A) | X17: -132.66733 | Y17: Pipe End Lx-Force (End A) | Z17: -137.39108 | AA17: Pipe End Lx-Force (End A) | AB17: -142.2394 | AC17: Pipe End Lx-Force (End A) | AD17: -147.39099 | AE17: Pipe End Lx-Force (End A) | AF17: -151.7794 | AG17: Pipe End Lx-Force (End A) | AH17: -156.53641 | AI17: Pipe End Lx-Force (End A) | AJ17: -165.29074
A18: Vessel1 Name | B18: Vessel1 | C18: Vessel1 Name | D18: Vessel1 | E18: Vessel1 Name | F18: Vessel1 | G18: Vessel1 Name | H18: Vessel1 | I18: Vessel1 Name | J18: Vessel1 | K18: Vessel1 Name | L18: Vessel1 | M18: Vessel1 Name | N18: Vessel1 | O18: Vessel1 Name | P18: Vessel1 | Q18: Vessel1 Name | R18: Vessel1 | S18: Vessel1 Name | T18: Vessel1 | U18: Vessel1 Name | V18: Vessel1 | W18: Vessel1 Name | X18: Vessel1 | Y18: Vessel1 Name | Z18: Vessel1 | AA18: Vessel1 Name | AB18: Vessel1 | AC18: Vessel1 Name | AD18: Vessel1 | AE18: Vessel1 Name | AF18: Vessel1 | AG18: Vessel1 Name | AH18: Vessel1 | AI18: Vessel1 Name | AJ18: Vessel1
A19: 8" x 14mm Type Name | B19: 8" x 14mm Type | C19: 8" x 14mm Type Name | D19: 8" x 14mm Type | E19: 8" x 14mm Type Name | F19: 8" x 14mm Type | G19: 8" x 14mm Type Name | H19: 8" x 14mm Type | I19: 8" x 14mm Type Name | J19: 8" x 14mm Type | K19: 8" x 14mm Type Name | L19: 8" x 14mm Type | M19: 8" x 14mm Type Name | N19: 8" x 14mm Type | O19: 8" x 14mm Type Name | P19: 8" x 14mm Type | Q19: 8" x 14mm Type Name | R19: 8" x 14mm Type | S19: 8" x 14mm Type Name | T19: 8" x 14mm Type | U19: 8" x 14mm Type Name | V19: 8" x 14mm Type | W19: 8" x 14mm Type Name | X19: 8" x 14mm Type | Y19: 8" x 14mm Type Name | Z19: 8" x 14mm Type | AA19: 8" x 14mm Type Name | AB19: 8" x 14mm Type | AC19: 8" x 14mm Type Name | AD19: 8" x 14mm Type | AE19: 8" x 14mm Type Name | AF19: 8" x 14mm Type | AG19: 8" x 14mm Type Name | AH19: 8" x 14mm Type | AI19: 8" x 14mm Type Name | AJ19: 8" x 14mm Type
A20: Top End Declination | B20: 140 | C20: Top End Declination | D20: 140 | E20: Top End Declination | F20: 140 | G20: Top End Declination | H20: 140 | I20: Top End Declination | J20: 140 | K20: Top End Declination | L20: 140 | M20: Top End Declination | N20: 140 | O20: Top End Declination | P20: 140 | Q20: Top End Declination | R20: 140 | S20: Top End Declination | T20: 140 | U20: Top End Declination | V20: 140 | W20: Top End Declination | X20: 140 | Y20: Top End Declination | Z20: 140 | AA20: Top End Declination | AB20: 140 | AC20: Top End Declination | AD20: 140 | AE20: Top End Declination | AF20: 140 | AG20: Top End Declination | AH20: 140 | AI20: Top End Declination | AJ20: 140
A21: Environment WaterDepth | B21: 120 | C21: Environment WaterDepth | D21: 120 | E21: Environment WaterDepth | F21: 120 | G21: Environment WaterDepth | H21: 120 | I21: Environment WaterDepth | J21: 120 | K21: Environment WaterDepth | L21: 120 | M21: Environment WaterDepth | N21: 120 | O21: Environment WaterDepth | P21: 120 | Q21: Environment WaterDepth | R21: 120 | S21: Environment WaterDepth | T21: 120 | U21: Environment WaterDepth | V21: 120 | W21: Environment WaterDepth | X21: 120 | Y21: Environment WaterDepth | Z21: 120 | AA21: Environment WaterDepth | AB21: 120 | AC21: Environment WaterDepth | AD21: 120 | AE21: Environment WaterDepth | AF21: 120 | AG21: Environment WaterDepth | AH21: 120 | AI21: Environment WaterDepth | AJ21: 120
A22: Environment SeabedSlope | B22: 0 | C22: Environment SeabedSlope | D22: 0 | E22: Environment SeabedSlope | F22: 0 | G22: Environment SeabedSlope | H22: 0 | I22: Environment SeabedSlope | J22: 0 | K22: Environment SeabedSlope | L22: 0 | M22: Environment SeabedSlope | N22: 0 | O22: Environment SeabedSlope | P22: 0 | Q22: Environment SeabedSlope | R22: 0 | S22: Environment SeabedSlope | T22: 0 | U22: Environment SeabedSlope | V22: 0 | W22: Environment SeabedSlope | X22: 0 | Y22: Environment SeabedSlope | Z22: 0 | AA22: Environment SeabedSlope | AB22: 0 | AC22: Environment SeabedSlope | AD22: 0 | AE22: Environment SeabedSlope | AF22: 0 | AG22: Environment SeabedSlope | AH22: 0 | AI22: Environment SeabedSlope | AJ22: 0
A23: Environment RefCurrentSpeed | B23: 0 | C23: Environment RefCurrentSpeed | D23: 0 | E23: Environment RefCurrentSpeed | F23: 0 | G23: Environment RefCurrentSpeed | H23: 0 | I23: Environment RefCurrentSpeed | J23: 0 | K23: Environment RefCurrentSpeed | L23: 0 | M23: Environment RefCurrentSpeed | N23: 0 | O23: Environment RefCurrentSpeed | P23: 0 | Q23: Environment RefCurrentSpeed | R23: 0 | S23: Environment RefCurrentSpeed | T23: 0 | U23: Environment RefCurrentSpeed | V23: 0 | W23: Environment RefCurrentSpeed | X23: 0 | Y23: Environment RefCurrentSpeed | Z23: 0 | AA23: Environment RefCurrentSpeed | AB23: 0 | AC23: Environment RefCurrentSpeed | AD23: 0 | AE23: Environment RefCurrentSpeed | AF23: 0 | AG23: Environment RefCurrentSpeed | AH23: 0 | AI23: Environment RefCurrentSpeed | AJ23: 0
A24: Environment CurrentFactor[1] | B24: 1 | C24: Environment CurrentFactor[1] | D24: 1 | E24: Environment CurrentFactor[1] | F24: 1 | G24: Environment CurrentFactor[1] | H24: 1 | I24: Environment CurrentFactor[1] | J24: 1 | K24: Environment CurrentFactor[1] | L24: 1 | M24: Environment CurrentFactor[1] | N24: 1 | O24: Environment CurrentFactor[1] | P24: 1 | Q24: Environment CurrentFactor[1] | R24: 1 | S24: Environment CurrentFactor[1] | T24: 1 | U24: Environment CurrentFactor[1] | V24: 1 | W24: Environment CurrentFactor[1] | X24: 1 | Y24: Environment CurrentFactor[1] | Z24: 1 | AA24: Environment CurrentFactor[1] | AB24: 1 | AC24: Environment CurrentFactor[1] | AD24: 1 | AE24: Environment CurrentFactor[1] | AF24: 1 | AG24: Environment CurrentFactor[1] | AH24: 1 | AI24: Environment CurrentFactor[1] | AJ24: 1
A25: Environment CurrentFactor[2] | B25: 1 | C25: Environment CurrentFactor[2] | D25: 1 | E25: Environment CurrentFactor[2] | F25: 1 | G25: Environment CurrentFactor[2] | H25: 1 | I25: Environment CurrentFactor[2] | J25: 1 | K25: Environment CurrentFactor[2] | L25: 1 | M25: Environment CurrentFactor[2] | N25: 1 | O25: Environment CurrentFactor[2] | P25: 1 | Q25: Environment CurrentFactor[2] | R25: 1 | S25: Environment CurrentFactor[2] | T25: 1 | U25: Environment CurrentFactor[2] | V25: 1 | W25: Environment CurrentFactor[2] | X25: 1 | Y25: Environment CurrentFactor[2] | Z25: 1 | AA25: Environment CurrentFactor[2] | AB25: 1 | AC25: Environment CurrentFactor[2] | AD25: 1 | AE25: Environment CurrentFactor[2] | AF25: 1 | AG25: Environment CurrentFactor[2] | AH25: 1 | AI25: Environment CurrentFactor[2] | AJ25: 1
A26: Environment RefCurrentDirection | B26: 180 | C26: Environment RefCurrentDirection | D26: 180 | E26: Environment RefCurrentDirection | F26: 180 | G26: Environment RefCurrentDirection | H26: 180 | I26: Environment RefCurrentDirection | J26: 180 | K26: Environment RefCurrentDirection | L26: 180 | M26: Environment RefCurrentDirection | N26: 180 | O26: Environment RefCurrentDirection | P26: 180 | Q26: Environment RefCurrentDirection | R26: 180 | S26: Environment RefCurrentDirection | T26: 180 | U26: Environment RefCurrentDirection | V26: 180 | W26: Environment RefCurrentDirection | X26: 180 | Y26: Environment RefCurrentDirection | Z26: 180 | AA26: Environment RefCurrentDirection | AB26: 180 | AC26: Environment RefCurrentDirection | AD26: 180 | AE26: Environment RefCurrentDirection | AF26: 180 | AG26: Environment RefCurrentDirection | AH26: 180 | AI26: Environment RefCurrentDirection | AJ26: 180
A27: API CODE CHECK SMYS | B27: 358000 | C27: API CODE CHECK SMYS | D27: 358000 | E27: API CODE CHECK SMYS | F27: 358000 | G27: API CODE CHECK SMYS | H27: 358000 | I27: API CODE CHECK SMYS | J27: 358000 | K27: API CODE CHECK SMYS | L27: 358000 | M27: API CODE CHECK SMYS | N27: 358000 | O27: API CODE CHECK SMYS | P27: 358000 | Q27: API CODE CHECK SMYS | R27: 358000 | S27: API CODE CHECK SMYS | T27: 358000 | U27: API CODE CHECK SMYS | V27: 358000 | W27: API CODE CHECK SMYS | X27: 358000 | Y27: API CODE CHECK SMYS | Z27: 358000 | AA27: API CODE CHECK SMYS | AB27: 358000 | AC27: API CODE CHECK SMYS | AD27: 358000 | AE27: API CODE CHECK SMYS | AF27: 358000 | AG27: API CODE CHECK SMYS | AH27: 358000 | AI27: API CODE CHECK SMYS | AJ27: 358000
A28: Pipe API RP 1111 Max Combined | B28: 0.10007657 | C28: Pipe API RP 1111 Max Combined | D28: 0.093435553 | E28: Pipe API RP 1111 Max Combined | F28: 0.090247155 | G28: Pipe API RP 1111 Max Combined | H28: 0.092477493 | I28: Pipe API RP 1111 Max Combined | J28: 0.09485294 | K28: Pipe API RP 1111 Max Combined | L28: 0.097382718 | M28: Pipe API RP 1111 Max Combined | N28: 0.1000804 | O28: Pipe API RP 1111 Max Combined | P28: 0.10296751 | Q28: Pipe API RP 1111 Max Combined | R28: 0.10605642 | S28: Pipe API RP 1111 Max Combined | T28: 0.10936649 | U28: Pipe API RP 1111 Max Combined | V28: 0.11292794 | W28: Pipe API RP 1111 Max Combined | X28: 0.11676665 | Y28: Pipe API RP 1111 Max Combined | Z28: 0.12087917 | AA28: Pipe API RP 1111 Max Combined | AB28: 0.12511434 | AC28: Pipe API RP 1111 Max Combined | AD28: 0.12947937 | AE28: Pipe API RP 1111 Max Combined | AF28: 0.13398093 | AG28: Pipe API RP 1111 Max Combined | AH28: 0.13862417 | AI28: Pipe API RP 1111 Max Combined | AJ28: 0.14349928
A29: Pipe Minimum Tension | B29: 54.346949 | C29: Pipe Minimum Tension | D29: 57.735303 | E29: Pipe Minimum Tension | F29: 61.400542 | G29: Pipe Minimum Tension | H29: 65.313411 | I29: Pipe Minimum Tension | J29: 69.521471 | K29: Pipe Minimum Tension | L29: 74.044459 | M29: Pipe Minimum Tension | N29: 78.907428 | O29: Pipe Minimum Tension | P29: 84.149352 | Q29: Pipe Minimum Tension | R29: 89.813236 | S29: Pipe Minimum Tension | T29: 95.927502 | U29: Pipe Minimum Tension | V29: 102.54748 | W29: Pipe Minimum Tension | X29: 109.74542 | Y29: Pipe Minimum Tension | Z29: 117.48856 | AA29: Pipe Minimum Tension | AB29: 125.5224 | AC29: Pipe Minimum Tension | AD29: 133.85417 | AE29: Pipe Minimum Tension | AF29: 142.49127 | AG29: Pipe Minimum Tension | AH29: 151.42752 | AI29: Pipe Minimum Tension | AJ29: 160.84384

Sheet Range Graph Results
A1: Load Case001.sim | G1: Load Case002.sim | M1: Load Case003.sim | S1: Load Case004.sim | Y1: Load Case005.sim | AE1: Load Case006.sim | AK1: Load Case007.sim | AQ1: Load Case008.sim | AW1: Load Case009.sim | BC1: Load Case010.sim | BI1: Load Case011.sim | BO1: Load Case012.sim | BU1: Load Case013.sim | CA1: Load Case014.sim | CG1: Load Case015.sim | CM1: Load Case016.sim | CS1: Load Case017.sim | CY1: Load Case018.sim
A2: Pipe Declination | D2: Max Von Mises Stress | G2: Pipe Declination | J2: Max Von Mises Stress | M2: Pipe Declination | P2: Max Von Mises Stress | S2: Pipe Declination | V2: Max Von Mises Stress | Y2: Pipe Declination | AB2: Max Von Mises Stress | AE2: Pipe Declination | AH2: Max Von Mises Stress | AK2: Pipe Declination | AN2: Max Von Mises Stress | AQ2: Pipe Declination | AT2: Max Von Mises Stress | AW2: Pipe Declination | AZ2: Max Von Mises Stress | BC2: Pipe Declination | BF2: Max Von Mises Stress | BI2: Pipe Declination | BL2: Max Von Mises Stress | BO2: Pipe Declination | BR2: Max Von Mises Stress | BU2: Pipe Declination | BX2: Max Von Mises Stress | CA2: Pipe Declination | CD2: Max Von Mises Stress | CG2: Pipe Declination | CJ2: Max Von Mises Stress | CM2: Pipe Declination | CP2: Max Von Mises Stress | CS2: Pipe Declination | CV2: Max Von Mises Stress | CY2: Pipe Declination | DB2: Max Von Mises Stress
A3: Arc Length | B3: Declination | C3: Declination Direction | D3: Arc Length | E3: Max von Mises Stress | F3: Allowable Stress | G3: Arc Length | H3: Declination | I3: Declination Direction | J3: Arc Length | K3: Max von Mises Stress | L3: Allowable Stress | M3: Arc Length | N3: Declination | O3: Declination Direction | P3: Arc Length | Q3: Max von Mises Stress | R3: Allowable Stress | S3: Arc Length | T3: Declination | U3: Declination Direction | V3: Arc Length | W3: Max von Mises Stress | X3: Allowable Stress | Y3: Arc Length | Z3: Declination | AA3: Declination Direction | AB3: Arc Length | AC3: Max von Mises Stress | AD3: Allowable Stress | AE3: Arc Length | AF3: Declination | AG3: Declination Direction | AH3: Arc Length | AI3: Max von Mises Stress | AJ3: Allowable Stress | AK3: Arc Length | AL3: Declination | AM3: Declination Direction | AN3: Arc Length | AO3: Max von Mises Stress | AP3: Allowable Stress | AQ3: Arc Length | AR3: Declination | AS3: Declination Direction | AT3: Arc Length | AU3: Max von Mises Stress | AV3: Allowable Stress | AW3: Arc Length | AX3: Declination | AY3: Declination Direction | AZ3: Arc Length | BA3: Max von Mises Stress | BB3: Allowable Stress | BC3: Arc Length | BD3: Declination | BE3: Declination Direction | BF3: Arc Length | BG3: Max von Mises Stress | BH3: Allowable Stress | BI3: Arc Length | BJ3: Declination | BK3: Declination Direction | BL3: Arc Length | BM3: Max von Mises Stress | BN3: Allowable Stress | BO3: Arc Length | BP3: Declination | BQ3: Declination Direction | BR3: Arc Length | BS3: Max von Mises Stress | BT3: Allowable Stress | BU3: Arc Length | BV3: Declination | BW3: Declination Direction | BX3: Arc Length | BY3: Max von Mises Stress | BZ3: Allowable Stress | CA3: Arc Length | CB3: Declination | CC3: Declination Direction | CD3: Arc Length | CE3: Max von Mises Stress | CF3: Allowable Stress | CG3: Arc Length | CH3: Declination | CI3: Declination Direction | CJ3: Arc Length | CK3: Max von Mises Stress | CL3: Allowable Stress | CM3: Arc Length | CN3: Declination | CO3: Declination Direction | CP3: Arc Length | CQ3: Max von Mises Stress | CR3: Allowable Stress | CS3: Arc Length | CT3: Declination | CU3: Declination Direction | CV3: Arc Length | CW3: Max von Mises Stress | CX3: Allowable Stress | CY3: Arc Length | CZ3: Declination | DA3: Declination Direction | DB3: Arc Length | DC3: Max von Mises Stress | DD3: Allowable Stress | DG3: Declination Direction | DM3: Declination Direction
